Workbook

Sheet Anleitung!!!
A1: Die Benutzer Oberfläche findet Ihr in "Blatt1"
A2: nur Blatt1 ist für User relevant
A6: geplante Funktionen die noch fehlen:
A7: Ergebnisse sind noch nicht 100% korrekt da noch ein wichtiger Filter fehlt
A8: Beschreibungen zu jeder Funktion anzeigen
A9: Beschreibungen zu jedem Effekt anzeigen
A10: Gain Faktor Rechner
A11: UI verändert - das alles Benutzerfreundlicher wird
A12: Erklärungen hinzufügen in der Benutzeroberfläche
A13: Grundsätzliche Tips hinzufügen zur Profil Einstellung
A14: Priorisierung der Effekte einbauen
A15: Flug Simulationen Unterstützen
... A26: Version0.6.0

Sheet Blatt1
A1: 1. Wähle hier aus welcher Effekt betroffen ist >>>> | B1: Sway to Roll - Main Plattform | C1: {=IFERROR(INDEX(Filter!$B:$B,_xlfn.AGGREGATE(15,6,Filter!$C:$C,ROW(A1))),"")} -> Stärke | D1: {=IFERROR(INDEX(Filter!$G:$G,_xlfn.AGGREGATE(15,6,Filter!$H:$H,ROW(A1))),"")} -> Effect scaling - Uniform scaling - Separate acceleration and decleration | E1: {=_xlfn._xlws.FILTER(Blatt1!D:D,ISNUMBER(MATCH(Blatt1!D:D,_xlfn._xlws.FILTER(Blatt5!A2:A456,Blatt5!B2:B456=Blatt1!B1),0)))} -> Effect Tuner
A2: 2. Wähle hier was Dich an dem Effekt stört oder was einfach nicht passt >>> | B2: Effekt ist viel zu heftig, zu stark | C2: {=IFERROR(INDEX(Filter!$B:$B,_xlfn.AGGREGATE(15,6,Filter!$C:$C,ROW(A2))),"")} -> Geschwindigkeit | D2: {=IFERROR(INDEX(Filter!$G:$G,_xlfn.AGGREGATE(15,6,Filter!$H:$H,ROW(A2))),"")} -> Effect scaling - Uniform scaling - Separate front and back pitch | E2: Effekt Gain
A3: 3. Ergebnis auslesen in Spalte E, dort stehen jetzt die möglichen | C3: {=IFERROR(INDEX(Filter!$B:$B,_xlfn.AGGREGATE(15,6,Filter!$C:$C,ROW(A3))),"")} -> Beschleunigung | D3: {=IFERROR(INDEX(Filter!$G:$G,_xlfn.AGGREGATE(15,6,Filter!$H:$H,ROW(A3))),"")} -> Effect speed limiter - Acivity range based speed reduction | E3: Enable adaptive Washout
A4: Einstellungen für Dein Problem | C4: {=IFERROR(INDEX(Filter!$B:$B,_xlfn.AGGREGATE(15,6,Filter!$C:$C,ROW(A4))),"")} -> Smoothness | D4: {=IFERROR(INDEX(Filter!$G:$G,_xlfn.AGGREGATE(15,6,Filter!$H:$H,ROW(A4))),"")} -> Effect Speed Limiter - Enable effect axis speed limiter | E4: Global Motion Smoothing
A5: Zelle anklicken, dann Dropdown am Pfeil links öffnen | C5: {=IFERROR(INDEX(Filter!$B:$B,_xlfn.AGGREGATE(15,6,Filter!$C:$C,ROW(A5))),"")} -> Verfahrweg | D5: {=IFERROR(INDEX(Filter!$G:$G,_xlfn.AGGREGATE(15,6,Filter!$H:$H,ROW(A5))),"")} -> Effect Tuner | E5: Input Limit
C6: {=IFERROR(INDEX(Filter!$B:$B,_xlfn.AGGREGATE(15,6,Filter!$C:$C,ROW(A6))),"")} -> Details | D6: {=IFERROR(INDEX(Filter!$G:$G,_xlfn.AGGREGATE(15,6,Filter!$H:$H,ROW(A6))),"")} -> Effekt Gain | E6: Main Plattform Gain
C7: {=IFERROR(INDEX(Filter!$B:$B,_xlfn.AGGREGATE(15,6,Filter!$C:$C,ROW(A7))),"")} -> Telemetrie - Input Limit | D7: {=IFERROR(INDEX(Filter!$G:$G,_xlfn.AGGREGATE(15,6,Filter!$H:$H,ROW(A7))),"")} -> Enable adaptive Washout | E7: Motion Gain
A8: Bitte DRINGEND beachten: | C8: {=IFERROR(INDEX(Filter!$B:$B,_xlfn.AGGREGATE(15,6,Filter!$C:$C,ROW(A8))),"")} -> Totzone | D8: {=IFERROR(INDEX(Filter!$G:$G,_xlfn.AGGREGATE(15,6,Filter!$H:$H,ROW(A8))),"")} -> Front / rear bias (Center of rotation) | E8: Motion Range
A9: Es handelt sich um eine sehr frühe Version des Motion Helpers | C9: {=IFERROR(INDEX(Filter!$B:$B,_xlfn.AGGREGATE(15,6,Filter!$C:$C,ROW(A9))),"")} -> Clipping - Overflow - Effekt Überlagerung | D9: {=IFERROR(INDEX(Filter!$G:$G,_xlfn.AGGREGATE(15,6,Filter!$H:$H,ROW(A9))),"")} -> Global Motion Smoothing | E9: Noise Filter
A10: Ergebnisse stimmen noch nicht zu 100% | C10: {=IFERROR(INDEX(Filter!$B:$B,_xlfn.AGGREGATE(15,6,Filter!$C:$C,ROW(A10))),"")} | D10: {=IFERROR(INDEX(Filter!$G:$G,_xlfn.AGGREGATE(15,6,Filter!$H:$H,ROW(A10))),"")} -> Haptics Effect Gain | E10: Noise Filter - Target Frequenzies
A11: Es fehlen noch sehr viele mögliche Einstellungen | C11: {=IFERROR(INDEX(Filter!$B:$B,_xlfn.AGGREGATE(15,6,Filter!$C:$C,ROW(A11))),"")} | D11: {=IFERROR(INDEX(Filter!$G:$G,_xlfn.AGGREGATE(15,6,Filter!$H:$H,ROW(A11))),"")} -> Haptics Gain | E11: Record (Telemetrie)
A12: Der Motion Helper liefert im Moment nur einige der Einstellungen, noch lange nicht alle | C12: {=IFERROR(INDEX(Filter!$B:$B,_xlfn.AGGREGATE(15,6,Filter!$C:$C,ROW(A12))),"")} | D12: {=IFERROR(INDEX(Filter!$G:$G,_xlfn.AGGREGATE(15,6,Filter!$H:$H,ROW(A12))),"")} -> Input Limit | E12: Response Curve - Dead zone (Percent)
C13: {=IFERROR(INDEX(Filter!$B:$B,_xlfn.AGGREGATE(15,6,Filter!$C:$C,ROW(A13))),"")} | D13: {=IFERROR(INDEX(Filter!$G:$G,_xlfn.AGGREGATE(15,6,Filter!$H:$H,ROW(A13))),"")} -> Main Plattform Gain | E13: Response Curve - Dead Zone exit kick (Percent)
C14: {=IFERROR(INDEX(Filter!$B:$B,_xlfn.AGGREGATE(15,6,Filter!$C:$C,ROW(A14))),"")} | D14: {=IFERROR(INDEX(Filter!$G:$G,_xlfn.AGGREGATE(15,6,Filter!$H:$H,ROW(A14))),"")} -> Motion Gain | E14: Response Curve - Dead Zone exit smoothing (Percent)
C15: {=IFERROR(INDEX(Filter!$B:$B,_xlfn.AGGREGATE(15,6,Filter!$C:$C,ROW(A15))),"")} | D15: {=IFERROR(INDEX(Filter!$G:$G,_xlfn.AGGREGATE(15,6,Filter!$H:$H,ROW(A15))),"")} -> Motion Range | E15: Response Curve - Flip output sign
C16: {=IFERROR(INDEX(Filter!$B:$B,_xlfn.AGGREGATE(15,6,Filter!$C:$C,ROW(A16))),"")} | D16: {=IFERROR(INDEX(Filter!$G:$G,_xlfn.AGGREGATE(15,6,Filter!$H:$H,ROW(A16))),"")} -> Noise Filter | E16: Response Curve - Gamma Factor
C17: {=IFERROR(INDEX(Filter!$B:$B,_xlfn.AGGREGATE(15,6,Filter!$C:$C,ROW(A17))),"")} | D17: {=IFERROR(INDEX(Filter!$G:$G,_xlfn.AGGREGATE(15,6,Filter!$H:$H,ROW(A17))),"")} -> Noise Filter - Target Frequenzies | E17: Smoothing
C18: {=IFERROR(INDEX(Filter!$B:$B,_xlfn.AGGREGATE(15,6,Filter!$C:$C,ROW(A18))),"")} | D18: {=IFERROR(INDEX(Filter!$G:$G,_xlfn.AGGREGATE(15,6,Filter!$H:$H,ROW(A18))),"")} -> Record (Telemetrie) | E18: Soft Limiter - Dampening range
C19: {=IFERROR(INDEX(Filter!$B:$B,_xlfn.AGGREGATE(15,6,Filter!$C:$C,ROW(A19))),"")} | D19: {=IFERROR(INDEX(Filter!$G:$G,_xlfn.AGGREGATE(15,6,Filter!$H:$H,ROW(A19))),"")} -> Response Curve - Dead zone (Percent) | E19: Soft Limiter - Dynamic input range compression
C20: {=IFERROR(INDEX(Filter!$B:$B,_xlfn.AGGREGATE(15,6,Filter!$C:$C,ROW(A20))),"")} | D20: {=IFERROR(INDEX(Filter!$G:$G,_xlfn.AGGREGATE(15,6,Filter!$H:$H,ROW(A20))),"")} -> Response Curve - Dead Zone exit kick (Percent) | E20: Washout (Return to Center)
C21: {=IFERROR(INDEX(Filter!$B:$B,_xlfn.AGGREGATE(15,6,Filter!$C:$C,ROW(A21))),"")} | D21: {=IFERROR(INDEX(Filter!$G:$G,_xlfn.AGGREGATE(15,6,Filter!$H:$H,ROW(A21))),"")} -> Response Curve - Dead Zone exit smoothing (Percent)
C22: {=IFERROR(INDEX(Filter!$B:$B,_xlfn.AGGREGATE(15,6,Filter!$C:$C,ROW(A22))),"")} | D22: {=IFERROR(INDEX(Filter!$G:$G,_xlfn.AGGREGATE(15,6,Filter!$H:$H,ROW(A22))),"")} -> Response Curve - Flip output sign
C23: {=IFERROR(INDEX(Filter!$B:$B,_xlfn.AGGREGATE(15,6,Filter!$C:$C,ROW(A23))),"")} | D23: {=IFERROR(INDEX(Filter!$G:$G,_xlfn.AGGREGATE(15,6,Filter!$H:$H,ROW(A23))),"")} -> Response Curve - Gamma Factor
C24: {=IFERROR(INDEX(Filter!$B:$B,_xlfn.AGGREGATE(15,6,Filter!$C:$C,ROW(A24))),"")} | D24: {=IFERROR(INDEX(Filter!$G:$G,_xlfn.AGGREGATE(15,6,Filter!$H:$H,ROW(A24))),"")} -> Secondary Plattform Gain
C25: {=IFERROR(INDEX(Filter!$B:$B,_xlfn.AGGREGATE(15,6,Filter!$C:$C,ROW(A25))),"")} | D25: {=IFERROR(INDEX(Filter!$G:$G,_xlfn.AGGREGATE(15,6,Filter!$H:$H,ROW(A25))),"")} -> Secondary Surge Gain
C26: {=IFERROR(INDEX(Filter!$B:$B,_xlfn.AGGREGATE(15,6,Filter!$C:$C,ROW(A26))),"")} | D26: {=IFERROR(INDEX(Filter!$G:$G,_xlfn.AGGREGATE(15,6,Filter!$H:$H,ROW(A26))),"")} -> Smoothing
C27: {=IFERROR(INDEX(Filter!$B:$B,_xlfn.AGGREGATE(15,6,Filter!$C:$C,ROW(A27))),"")} | D27: {=IFERROR(INDEX(Filter!$G:$G,_xlfn.AGGREGATE(15,6,Filter!$H:$H,ROW(A27))),"")} -> Soft Limiter - Dampening range
C28: {=IFERROR(INDEX(Filter!$B:$B,_xlfn.AGGREGATE(15,6,Filter!$C:$C,ROW(A28))),"")} | D28: {=IFERROR(INDEX(Filter!$G:$G,_xlfn.AGGREGATE(15,6,Filter!$H:$H,ROW(A28))),"")} -> Soft Limiter - Dynamic input range compression
C29: {=IFERROR(INDEX(Filter!$B:$B,_xlfn.AGGREGATE(15,6,Filter!$C:$C,ROW(A29))),"")} | D29: {=IFERROR(INDEX(Filter!$G:$G,_xlfn.AGGREGATE(15,6,Filter!$H:$H,ROW(A29))),"")} -> Source Algorythm - Traction loss angle - Lateral velocity
C30: {=IFERROR(INDEX(Filter!$B:$B,_xlfn.AGGREGATE(15,6,Filter!$C:$C,ROW(A30))),"")} | D30: {=IFERROR(INDEX(Filter!$G:$G,_xlfn.AGGREGATE(15,6,Filter!$H:$H,ROW(A30))),"")} -> Surge Gain
C31: {=IFERROR(INDEX(Filter!$B:$B,_xlfn.AGGREGATE(15,6,Filter!$C:$C,ROW(A31))),"")} | D31: {=IFERROR(INDEX(Filter!$G:$G,_xlfn.AGGREGATE(15,6,Filter!$H:$H,ROW(A31))),"")} -> Synchronize filtering and input limit settings with Heave
C32: {=IFERROR(INDEX(Filter!$B:$B,_xlfn.AGGREGATE(15,6,Filter!$C:$C,ROW(A32))),"")} | D32: {=IFERROR(INDEX(Filter!$G:$G,_xlfn.AGGREGATE(15,6,Filter!$H:$H,ROW(A32))),"")} -> Synchronize filtering and input limit settings with Pitch
... C360: {=IFERROR(INDEX(Filter!$B:$B,_xlfn.AGGREGATE(15,6,Filter!$C:$C,ROW(A360))),"")} | D360: {=IFERROR(INDEX(Filter!$G:$G,_xlfn.AGGREGATE(15,6,Filter!$H:$H,ROW(A360))),"")}
D361: {=IFERROR(INDEX(Filter!$G:$G,_xlfn.AGGREGATE(15,6,Filter!$H:$H,ROW(A361))),"")}
D362: {=IFERROR(INDEX(Filter!$G:$G,_xlfn.AGGREGATE(15,6,Filter!$H:$H,ROW(A362))),"")}
D363: {=IFERROR(INDEX(Filter!$G:$G,_xlfn.AGGREGATE(15,6,Filter!$H:$H,ROW(A363))),"")}
D364: {=IFERROR(INDEX(Filter!$G:$G,_xlfn.AGGREGATE(15,6,Filter!$H:$H,ROW(A364))),"")}
D365: {=IFERROR(INDEX(Filter!$G:$G,_xlfn.AGGREGATE(15,6,Filter!$H:$H,ROW(A365))),"")}
D366: {=IFERROR(INDEX(Filter!$G:$G,_xlfn.AGGREGATE(15,6,Filter!$H:$H,ROW(A366))),"")}
D367: {=IFERROR(INDEX(Filter!$G:$G,_xlfn.AGGREGATE(15,6,Filter!$H:$H,ROW(A367))),"")}
...

Sheet Begriffe
A1: Begriffe | B1: Erklärung
A2: Effekt Gain | B2: Der Effekt Gain ändert die Stärke (Intensity) des jeweiligen Effektes
B3: Speed ändert sich
B4: Beschleunigung ändert sich
B5: genutzter Verfahrweg ändert sich in Prozent in Abhängigkeit des eingestellten maximalen Weges
B6: gefühlte Stärke (Intensity) ändert sich
B7: Werte: 0-100%
A8: Motion Gain / Globaler Gain | B8: Der Motion Gain ändert die Stärke (Intensity) Global für alle Effekte gleichzeitg
B9: Speed ändert sich
B10: Beschleunigung ändert sich
B11: genutzter Verfahrweg ändert sich in Prozent in Abhängigkeit des eingestellten maximalen Weges
B12: gefühlte Stärke (Intensity) ändert sich
B13: Werte: 0-100%
A14: Plattform Gain / Zusatz Element Gain | B14: Der Motion Gain ändert die Stärke (Intensity) für alle Effekte der Plattform / des jeweilgen Zusatz Elementes
B15: Speed ändert sich
B16: Beschleunigung ändert sich
B17: genutzter Verfahrweg ändert sich in Prozent in Abhängigkeit des eingestellten maximalen Weges
B18: gefühlte Stärke (Intensity) ändert sich
B19: Werte: 0-100%
A20: Input Limit | B20: Mit dem Input Limit wird bestimmt, wie viel der ankommenden Telemetrie für den Effekt verwendet wird >> Ist der Input Limit kleiner wie die tatsächlichen Telemetrie Daten, dann wird der eingesetzte nutzbare Verfahrweg schneller erreicht - Somit steigt die Stärke des Effektes massiv an
B21: dient als extremer Gain Verstärker!!!
B22: Telemetrie wird verstärkt
B23: Telemetrie greift früher
B24: Effekt wird massiv verstärkt
B25: Grenze des Weges wird früher erreicht, je niedriger der Wert eingestellt ist
B26: nur so niedrig wie nötig einstellen
B27: Speed ändert sich
B28: Beschleunigung ändert sich
B29: genutzter Verfahrweg ändert sich in Prozent in Abhängigkeit des eingestellten maximalen Weges
B30: gefühlte Stärke (Intensity) ändert sich
B31: Werte: Grenze wäre bei 0.1, wird man aber niemals so einstellen, Gain steigt dadurch expotentiell
B32: Input Limit kleiner wie Telemetrie = Gain steigt über 100% expotentiell!!!
A33: Motion Range (maximaler Verfahrweg) | B33: Mit der Motion Range wird fest gelegt, wieviel Verfahrweg vom Aktuator effektiv genutzt werden darf. Wichtig >> Bei Effekten der Plattform ist der angegebene Weg immer der Gesamtweg ( 30mm bedeutet also 15mm ins + und 15mm ins -) bei Zusatz Elementen wie Surge oder TL ist der angegebenen Wert immer sowohl ins Plus als auch ins Minus, NICHT der Gesamtweg (das bedeutet wenn man 150mm Verfahrweg im TL hat, darf als maximaler Weg nur 75mm angegeben werden, nicht 150mm)
B34: weniger Weg = mehr Speed
B35: weniger Weg = mehr Beschleunigung
B36: weniger Weg = weniger Bewegung
A37: Effect Smoothing | B37: Smoothing glättet den Effekt - macht Ihn weicher, langsamer, entstört oder bei niedrigen Werten ruppiger, härter, schneller.
B38: Effekt wird rauher oder smoother
B39: Effekt wird ruppiger oder träger
B40: Effekt wird schneller oder langsamer und Beschleunigung wird ebenfalls verstärkt oder verringert.
...

Sheet Effekte
A1: Effekte
A2: Global Motion
A3: Main Platform
A4: Pitch - Main Plattform
A5: Roll - Main Plattform
A6: Surge to Pitch - Main Plattform
A7: Sway to Roll - Main Plattform
A8: Heave - Main Plattform
A9: Rear Traction Loss to Roll - Main Plattform
A10: Secondary Platform
A11: Secondary Pitch
A12: Secondary Roll
... A31: Audio to haptics - Haptic

Sheet Symptome
A1: Symptome
A2: Effekt zu schwach
A3: Effekt ist viel zu heftig, zu stark
A4: Effekt fährt zu langsam
A5: Effekt fährt zu schnell
A6: Effekt viel zu ruppig (auch bei niedrigen Verfahrweg) - zu hart
A7: Effekt kommt mir vor wie eingeschlafen, viel zu "gedämpft", ausgebremst - zu weich
A8: Es kommen zu wenig Details im Effekt an
A9: Es kommen übertriebene Details im Effekt an
A10: Details im unteren Bereich sind mir zu schwach
A11: Details im unteren Bereich sind mir zu stark / übertrieben
A12: Effekt bewegt sich in Situationen, wo ich das garnicht möchte (Unterer oder oberer Bereich)
... A49: Traction Loss funktioniert nicht

Sheet Faktoren
A1: Faktoren
A2: Stärke
A3: Geschwindigkeit
A4: Beschleunigung
A5: Smoothness
A6: Verfahrweg
A7: Details
A8: Störsignale - Zittern - unkontrolliertes wackeln
A9: Clipping - Overflow - Effekt Überlagerung
A10: Telemetrie - Input Limit
A11: Totzone
A12: Verfahr Richtung
... A15: Balance

Sheet Funktionen
A1: Funktionen | B1: Erläuterung
A2: Effekt Gain
A3: Motion Gain
A4: Main Plattform Gain
A5: Secondary Plattform Gain
A6: Surge Gain
A7: Secondary Surge Gain
A8: Traction Loss Gain
A9: Haptics Gain
A10: Haptics Effect Gain
A11: Input Limit
A12: Motion Range
A13: Global Motion Smoothing
... A26: Effect Tuner
A27: Effect scaling - Uniform scaling - Separate front and back pitch | B27: Pitch - Secondary Pitch
A28: Effect direction - Tilt forward when braking - Tilt backward when braking | B28: Surge to Pitch - Secondary Surge to pitch
A29: Effect scaling - Uniform scaling - Separate acceleration and decleration | B29: Surge to Pitch - Secondary Surge to pitch - Surge - Secondary Surge
A30: Effect enabled - disabled
A31: Effect direction - Lean outward when cornering - Lean inward when cornering | B31: Sway to roll - Secondary Sway to roll
A32: Effect direction - Up acceleration goes up - Down acceleration goes up | B32: Heave - Secondary Heave
A33: Source Algorythm - Traction loss angle - Lateral velocity | B33: Rear Traction Loss to Roll - Secondary Rear Traction Loss to Roll - Traction Loss
A34: Use turn rate at low speed - Turn rate sensibility | B34: Rear Traction Loss to Roll - Secondary Rear Traction Loss to Roll - Traction Loss
A35: Effect Speed Limiter - Enable effect axis speed limiter | B35: Rear Traction Loss to Roll - Secondary Rear Traction Loss to Roll - Traction Loss
A36: Effect speed limiter - Acivity range based speed reduction | B36: Rear Traction Loss to Roll - Secondary Rear Traction Loss to Roll - Traction Loss
A37: Synchronize filtering and input limit settings with Pitch | B37: Secondary Pitch
A38: Synchronize filtering and input limit settings with Roll | B38: Secondary Roll
A39: Synchronize filtering and input limit settings with Surge to pitch | B39: Secondary Surge to pitch
A40: Synchronize filtering and input limit settings with Sway to Roll | B40: Secondary Sway to roll
A41: Synchronize filtering and input limit settings with Heave | B41: Secondary Heave
A42: Front / rear bias (Center of rotation) | B42: Traction loss
A43: Record (Telemetrie)
A44: Effect direction - Move Forward when Braking - Move Backward when Braking | B44: Surge - Secondary Surge | C44: noch hinzufügen
A45: Effect direction - Slide Outward when cornering - Slide Inward when cornering | B45: Sway | C45: noch hinzufügen

Sheet Blatt2
A1: Effekt | B1: Symptom | C1: WENN(A1=Blatt1!$B$1;B1;"") - Symptome zu ausgewähltem Effekt filtern
A2: Global Motion | B2: Effekte überlagern sich - Clipping - Overflow | C2: =IF(A2=Blatt1!$B$1,B2,"")
A3: Global Motion | B3: Alle Effekte sind zu schwach | C3: =IF(A3=Blatt1!$B$1,B3,"")
A4: Global Motion | B4: Alle Effekte sind viel zu heftig, zu stark | C4: =IF(A4=Blatt1!$B$1,B4,"")
A5: Global Motion | B5: Alle Effekte fahren zu langsam | C5: =IF(A5=Blatt1!$B$1,B5,"")
A6: Global Motion | B6: Alle Effekte fahren zu schnell | C6: =IF(A6=Blatt1!$B$1,B6,"")
A7: Global Motion | B7: Alle Effekte sind irgendwie zu ruppig | C7: =IF(A7=Blatt1!$B$1,B7,"")
A8: Global Motion | B8: Alle Effekte sind mir zu gedämpft, zu ruhig, wie ausgebremst | C8: =IF(A8=Blatt1!$B$1,B8,"")
A9: Global Motion | B9: Der Verfahrweg in den Effekten ist mir zu wenig | C9: =IF(A9=Blatt1!$B$1,B9,"")
A10: Global Motion | B10: Der Verfahrweg in den Effekten ist mir zu viel | C10: =IF(A10=Blatt1!$B$1,B10,"")
A11: Global Motion | B11: Ich kenne die Werte aus den Effekten noch nicht, was dort an Telemetrie ankommt aus dem Spiel (Input) | C11: =IF(A11=Blatt1!$B$1,B11,"")
A12: Global Motion | B12: Die Effekte sind lahm, ich habe das Gefühl sie beschleunigen zu langsam | C12: =IF(A12=Blatt1!$B$1,B12,"")
A13: Global Motion | B13: Die Effekte sind übertrieben hart, ich habe das Gefühl sie beschleunigen zu schnell | C13: =IF(A13=Blatt1!$B$1,B13,"")
... A484: Audio to haptics - Haptic | B484: Effekt Funktioniert garnicht | C484: =IF(A484=Blatt1!$B$1,B484,"")

Sheet Blatt3
A1: Symptome | B1: Faktoren | C1: WENN(A1=Blatt1!$B$2;B1;"")
A2: Effekt zu schwach | B2: Stärke | C2: =IF(A2=Blatt1!$B$2,B2,"") | D2: groß
A3: Effekt zu schwach | B3: Geschwindigkeit | C3: =IF(A3=Blatt1!$B$2,B3,"") | D3: mittel
A4: Effekt zu schwach | B4: Beschleunigung | C4: =IF(A4=Blatt1!$B$2,B4,"") | D4: mittel
A5: Effekt zu schwach | B5: Smoothness | C5: =IF(A5=Blatt1!$B$2,B5,"") | D5: groß
A6: Effekt zu schwach | B6: Verfahrweg | C6: =IF(A6=Blatt1!$B$2,B6,"") | D6: groß
A7: Effekt zu schwach | B7: Details | C7: =IF(A7=Blatt1!$B$2,B7,"") | D7: mittel
A8: Effekt zu schwach | B8: Telemetrie - Input Limit | C8: =IF(A8=Blatt1!$B$2,B8,"") | D8: groß
A9: Effekt zu schwach | B9: Totzone | C9: =IF(A9=Blatt1!$B$2,B9,"") | D9: mittel
A10: Effekt ist viel zu heftig, zu stark | B10: Stärke | C10: =IF(A10=Blatt1!$B$2,B10,"") -> Stärke | D10: groß
A11: Effekt ist viel zu heftig, zu stark | B11: Geschwindigkeit | C11: =IF(A11=Blatt1!$B$2,B11,"") -> Geschwindigkeit | D11: mittel
A12: Effekt ist viel zu heftig, zu stark | B12: Beschleunigung | C12: =IF(A12=Blatt1!$B$2,B12,"") -> Beschleunigung | D12: mittel
A13: Effekt ist viel zu heftig, zu stark | B13: Smoothness | C13: =IF(A13=Blatt1!$B$2,B13,"") -> Smoothness | D13: groß
... A361: Traction Loss funktioniert nicht | B361: Balance | C361: =IF(A361=Blatt1!$B$2,B361,"") | D361: gering

Sheet Blatt4
A1: Verfahr Richtung | B1: Effect direction - Lean outward when cornering - Lean inward when cornering
A2: Verfahr Richtung | B2: Effect direction - Tilt forward when braking - Tilt backward when braking
A3: Verfahr Richtung | B3: Effect direction - Up acceleration goes up - Down acceleration goes up
A4: Aktivierung | B4: Effect enabled - disabled
A5: Unterstützung | B5: Effect enabled - disabled
A6: Aktivierung | B6: Effect scaling - Uniform scaling - Separate acceleration and decleration
A7: Clipping - Overflow - Effekt Überlagerung | B7: Effect scaling - Uniform scaling - Separate acceleration and decleration
A8: Details | B8: Effect scaling - Uniform scaling - Separate acceleration and decleration
A9: Störsignale - Zittern - unkontrolliertes wackeln | B9: Effect scaling - Uniform scaling - Separate acceleration and decleration
A10: Telemetrie - Input Limit | B10: Effect scaling - Uniform scaling - Separate acceleration and decleration
A11: Aktivierung | B11: Effect scaling - Uniform scaling - Separate front and back pitch
A12: Clipping - Overflow - Effekt Überlagerung | B12: Effect scaling - Uniform scaling - Separate front and back pitch
... A253: Verfahrweg | B253: Washout (Return to Center)

Sheet Blatt5
A1: Funktion | B1: Effekt
A2: Effekt Gain | B2: Pitch - Main Plattform
A3: Effekt Gain | B3: Roll - Main Plattform
A4: Effekt Gain | B4: Surge to Pitch - Main Plattform
A5: Effekt Gain | B5: Sway to Roll - Main Plattform
A6: Effekt Gain | B6: Heave - Main Plattform
A7: Effekt Gain | B7: Rear Traction Loss to Roll - Main Plattform
A8: Effekt Gain | B8: Secondary Pitch
A9: Effekt Gain | B9: Secondary Roll
A10: Effekt Gain | B10: Secondary Surge to Pitch
A11: Effekt Gain | B11: Secondary Sway to Roll
A12: Effekt Gain | B12: Secondary Heave
... A456: Record (Telemetrie) | B456: Yaw

Sheet Blatt6
A1: Faktor | B1: Effekt
A2: Stärke | B2: ABS trigger - Haptic | C2: x
A3: Smoothness | B3: ABS trigger - Haptic | C3: x
A4: Details | B4: ABS trigger - Haptic | C4: x
A5: Störsignale - Zittern - unkontrolliertes wackeln | B5: ABS trigger - Haptic | C5: x
A6: Clipping - Overflow - Effekt Überlagerung | B6: ABS trigger - Haptic | C6: x
A7: Aktivierung | B7: ABS trigger - Haptic | C7: x
A8: Stärke | B8: Audio to haptics - Haptic | C8: x
A9: Smoothness | B9: Audio to haptics - Haptic | C9: x
A10: Details | B10: Audio to haptics - Haptic | C10: x
A11: Störsignale - Zittern - unkontrolliertes wackeln | B11: Audio to haptics - Haptic | C11: x
A12: Clipping - Overflow - Effekt Überlagerung | B12: Audio to haptics - Haptic | C12: x
A13: Aktivierung | B13: Audio to haptics - Haptic | C13: x
... A43: Balance | B43: Global Motion | C43: x
A44: Stärke | B44: Global Traction Loss
A45: Geschwindigkeit | B45: Global Traction Loss
A46: Beschleunigung | B46: Global Traction Loss
A47: Smoothness | B47: Global Traction Loss
A48: Verfahrweg | B48: Global Traction Loss
A49: Details | B49: Global Traction Loss
A50: Störsignale - Zittern - unkontrolliertes wackeln | B50: Global Traction Loss
A51: Clipping - Overflow - Effekt Überlagerung | B51: Global Traction Loss
A52: Telemetrie - Input Limit | B52: Global Traction Loss
A53: Totzone | B53: Global Traction Loss
A54: Verfahr Richtung | B54: Global Traction Loss
A55: Aktivierung | B55: Global Traction Loss
... A379: Balance | B379: Yaw

Sheet Filter
A1: =Blatt2!C2 | B1: =Blatt3!C2 | C1: =IF(B1="","",ROW()) | F1: =IF(ISERROR(MATCH(Blatt4!A1,Filter!$B:$B,0)),"",ROW()) | G1: =IF(F1="","",Blatt4!B1) | H1: =IF(G1="","",IF(COUNTIF($G$1:G1,G1)=1,ROW(),""))
A2: =Blatt2!C3 | B2: =Blatt3!C3 | C2: =IF(B2="","",ROW()) | F2: =IF(ISERROR(MATCH(Blatt4!A2,Filter!$B:$B,0)),"",ROW()) | G2: =IF(F2="","",Blatt4!B2) | H2: =IF(G2="","",IF(COUNTIF($G$1:G2,G2)=1,ROW(),""))
A3: =Blatt2!C4 | B3: =Blatt3!C4 | C3: =IF(B3="","",ROW()) | F3: =IF(ISERROR(MATCH(Blatt4!A3,Filter!$B:$B,0)),"",ROW()) | G3: =IF(F3="","",Blatt4!B3) | H3: =IF(G3="","",IF(COUNTIF($G$1:G3,G3)=1,ROW(),""))
A4: =Blatt2!C5 | B4: =Blatt3!C5 | C4: =IF(B4="","",ROW()) | F4: =IF(ISERROR(MATCH(Blatt4!A4,Filter!$B:$B,0)),"",ROW()) | G4: =IF(F4="","",Blatt4!B4) | H4: =IF(G4="","",IF(COUNTIF($G$1:G4,G4)=1,ROW(),""))
A5: =Blatt2!C6 | B5: =Blatt3!C6 | C5: =IF(B5="","",ROW()) | F5: =IF(ISERROR(MATCH(Blatt4!A5,Filter!$B:$B,0)),"",ROW()) | G5: =IF(F5="","",Blatt4!B5) | H5: =IF(G5="","",IF(COUNTIF($G$1:G5,G5)=1,ROW(),""))
A6: =Blatt2!C7 | B6: =Blatt3!C7 | C6: =IF(B6="","",ROW()) | F6: =IF(ISERROR(MATCH(Blatt4!A6,Filter!$B:$B,0)),"",ROW()) | G6: =IF(F6="","",Blatt4!B6) | H6: =IF(G6="","",IF(COUNTIF($G$1:G6,G6)=1,ROW(),""))
A7: =Blatt2!C8 | B7: =Blatt3!C8 | C7: =IF(B7="","",ROW()) | F7: =IF(ISERROR(MATCH(Blatt4!A7,Filter!$B:$B,0)),"",ROW()) -> 7 | G7: =IF(F7="","",Blatt4!B7) -> Effect scaling - Uniform scaling - Separate acceleration and decleration | H7: =IF(G7="","",IF(COUNTIF($G$1:G7,G7)=1,ROW(),"")) -> 7
A8: =Blatt2!C9 | B8: =Blatt3!C9 | C8: =IF(B8="","",ROW()) | F8: =IF(ISERROR(MATCH(Blatt4!A8,Filter!$B:$B,0)),"",ROW()) -> 8 | G8: =IF(F8="","",Blatt4!B8) -> Effect scaling - Uniform scaling - Separate acceleration and decleration | H8: =IF(G8="","",IF(COUNTIF($G$1:G8,G8)=1,ROW(),""))
A9: =Blatt2!C10 | B9: =Blatt3!C10 -> Stärke | C9: =IF(B9="","",ROW()) -> 9 | F9: =IF(ISERROR(MATCH(Blatt4!A9,Filter!$B:$B,0)),"",ROW()) | G9: =IF(F9="","",Blatt4!B9) | H9: =IF(G9="","",IF(COUNTIF($G$1:G9,G9)=1,ROW(),""))
A10: =Blatt2!C11 | B10: =Blatt3!C11 -> Geschwindigkeit | C10: =IF(B10="","",ROW()) -> 10 | F10: =IF(ISERROR(MATCH(Blatt4!A10,Filter!$B:$B,0)),"",ROW()) -> 10 | G10: =IF(F10="","",Blatt4!B10) -> Effect scaling - Uniform scaling - Separate acceleration and decleration | H10: =IF(G10="","",IF(COUNTIF($G$1:G10,G10)=1,ROW(),""))
A11: =Blatt2!C12 | B11: =Blatt3!C12 -> Beschleunigung | C11: =IF(B11="","",ROW()) -> 11 | F11: =IF(ISERROR(MATCH(Blatt4!A11,Filter!$B:$B,0)),"",ROW()) | G11: =IF(F11="","",Blatt4!B11) | H11: =IF(G11="","",IF(COUNTIF($G$1:G11,G11)=1,ROW(),""))
A12: =Blatt2!C13 | B12: =Blatt3!C13 -> Smoothness | C12: =IF(B12="","",ROW()) -> 12 | F12: =IF(ISERROR(MATCH(Blatt4!A12,Filter!$B:$B,0)),"",ROW()) -> 12 | G12: =IF(F12="","",Blatt4!B12) -> Effect scaling - Uniform scaling - Separate front and back pitch | H12: =IF(G12="","",IF(COUNTIF($G$1:G12,G12)=1,ROW(),"")) -> 12
... A253: =Blatt2!C254 | B253: =Blatt3!C254 | C253: =IF(B253="","",ROW()) | F253: =IF(ISERROR(MATCH(Blatt4!A253,Filter!$B:$B,0)),"",ROW()) -> 253 | G253: =IF(F253="","",Blatt4!B253) -> Washout (Return to Center) | H253: =IF(G253="","",IF(COUNTIF($G$1:G253,G253)=1,ROW(),""))
A254: =Blatt2!C255 | B254: =Blatt3!C255 | C254: =IF(B254="","",ROW())
A255: =Blatt2!C256 | B255: =Blatt3!C256 | C255: =IF(B255="","",ROW())
A256: =Blatt2!C257 | B256: =Blatt3!C257 | C256: =IF(B256="","",ROW())
A257: =Blatt2!C258 | B257: =Blatt3!C258 | C257: =IF(B257="","",ROW())
A258: =Blatt2!C259 | B258: =Blatt3!C259 | C258: =IF(B258="","",ROW())
A259: =Blatt2!C260 | B259: =Blatt3!C260 | C259: =IF(B259="","",ROW())
A260: =Blatt2!C261 | B260: =Blatt3!C261 | C260: =IF(B260="","",ROW())
A261: =Blatt2!C262 | B261: =Blatt3!C262 | C261: =IF(B261="","",ROW())
A262: =Blatt2!C263 | B262: =Blatt3!C263 | C262: =IF(B262="","",ROW())
A263: =Blatt2!C264 | B263: =Blatt3!C264 | C263: =IF(B263="","",ROW())
A264: =Blatt2!C265 | B264: =Blatt3!C265 | C264: =IF(B264="","",ROW())
A265: =Blatt2!C266 | B265: =Blatt3!C266 | C265: =IF(B265="","",ROW())
... A360: =Blatt2!C361 | B360: =Blatt3!C361 | C360: =IF(B360="","",ROW())
A361: =Blatt2!C362
A362: =Blatt2!C363
A363: =Blatt2!C364
A364: =Blatt2!C365
A365: =Blatt2!C366
A366: =Blatt2!C367
A367: =Blatt2!C368
A368: =Blatt2!C369
A369: =Blatt2!C370
A370: =Blatt2!C371
A371: =Blatt2!C372
A372: =Blatt2!C373
... A483: =Blatt2!C484
B623: =Blatt3!C359
...
